<?xml version="1.0"?>
<robot xmlns:xacro="http://ros.org/wiki/xacro" >
		 
  <xacro:property name="MX64_WIDTH" value="0.0402" />
  <xacro:property name="MX64_HEIGHT" value="0.0611" />
  <xacro:property name="MX64_DEPTH" value="0.041" />

  <xacro:property name="MX106_WIDTH" value="0.0402" />
  <xacro:property name="MX106_HEIGHT" value="0.0651" />
  <xacro:property name="MX106_DEPTH" value="0.046" />

  <xacro:property name="Joint_Y_2_3" value="0.193" />
  <xacro:property name="Joint_Z_2_3" value="-0.075" />
  <xacro:property name="Joint_Y_3_4" value="0.055" />
  <xacro:property name="Joint_Y_4_5" value="0.263" />
  <xacro:property name="Joint_Y_5_6" value="0.04" />
  <xacro:property name="Joint_Y_6_7" value="0.057" />
  <xacro:property name="PI" value="3.14159"/>

  <xacro:macro name="palbator_arm" params="parent">

    <!-- <xacro:include filename="$(find cob_description)/gazebo/gazebo.urdf.xacro" /> -->

    <link name="palbator_arm_column">
      <inertial>
        <origin xyz="0 0 0.75" rpy="0 0 0" />
        <mass value="0.1"/>
        <inertia ixx="0.1" ixy="0" ixz="0" iyy="0.1" iyz="0" izz="0.1"/>
      </inertial>
      <visual>
        <origin xyz="0 0 0.75" rpy="0 0 0" />
        <geometry>
            <box size="0.08 0.08 1.5"/>
        </geometry>
        <material name="Gray_alu">
          <color rgba="0.5 0.5 0.5 1.0"/>
        </material>
      </visual>
    </link>

    <link name="palbator_arm_kinect_link" >
      <inertial>
        <origin xyz="0 0 0" rpy="0 0 0"/>
        <mass value="0.1"/>
        <inertia ixx="0.1" ixy="0" ixz="0" iyy="0.1" iyz="0" izz="0.1"/>
      </inertial>
      <visual>
        <geometry>
            <box size="0.05 .2 .05"/>
        </geometry>
          <origin xyz="0 0 0" rpy="0 0 0"/>
        <material name="Cyan">
          <color rgba="0 1.0 1.0 1.0"/>
        </material>          
      </visual>
    </link>  

    <link name="palbator_arm_column_link" >
      <inertial>
          <origin xyz="0 0 0" rpy="0 0 0"/>
          <mass value="0.1"/>
          <inertia ixx="0.1" ixy="0" ixz="0" iyy="0.1" iyz="0" izz="0.1"/>
      </inertial>
      <visual>
        <origin xyz="0 0 0" rpy="0 0 0" />
        <geometry>
            <cylinder length="0.2" radius="0.025" />
        </geometry>
      </visual>    
    </link>    

    <link name="palbator_arm_shoulder_link1" >
      <inertial>
        <origin xyz="0 ${(Joint_Y_2_3 + 0.02)/2} 0" rpy="0 0 0" />
        <mass value="0.1"/>
        <inertia ixx="0.1" ixy="0" ixz="0" iyy="0.1" iyz="0" izz="0.1"/>
      </inertial>
      <visual>
        <origin xyz="0 ${(Joint_Y_2_3 + 0.02)/2} 0" rpy="0 0 0" />
        <geometry>
            <box size="0.05 ${Joint_Y_2_3 + 0.02} 0.10"/>
        </geometry>
        <material name="Cyan">
        <color rgba="0 1.0 1.0 1.0"/>
      </material>
      </visual>
    </link>

    <link name="palbator_arm_shoulder_link2" >
      <inertial>
          <origin xyz="0 0.02 0" rpy="0 0 0" />
          <mass value="0.1"/>
          <inertia ixx="0.1" ixy="0" ixz="0" iyy="0.1" iyz="0" izz="0.1"/>
      </inertial>
      <visual>
        <origin xyz="0 0.02 0" rpy="0 0 0" />
        <geometry>
            <box size="0.11 0.075 0.055"/>
        </geometry>
      </visual>
    </link>

    <link name="palbator_arm_shoulder_link3" >
      <inertial>
          <origin xyz="0 ${Joint_Y_4_5 / 2} 0" rpy="0 0 0" />
          <mass value="0.1"/>
          <inertia ixx="0.1" ixy="0" ixz="0" iyy="0.1" iyz="0" izz="0.1"/>
      </inertial>
      <visual>
        <origin xyz="0 ${Joint_Y_4_5 / 2} 0" rpy="0 0 0" />
        <geometry>
            <box size="0.05 ${Joint_Y_4_5} 0.05"/>
        </geometry>
        <material name="Cyan">
        <color rgba="0 1.0 1.0 1.0"/>
      </material>
      </visual>
    </link>

    <link name="palbator_arm_wrist_link1" >
      <inertial>
          <origin xyz="0 ${Joint_Y_5_6 / 2} 0" rpy="0 0 0" />
          <mass value="0.1"/>
          <inertia ixx="0.1" ixy="0" ixz="0" iyy="0.1" iyz="0" izz="0.1"/>
      </inertial>
      <visual>
        <origin xyz="0 ${Joint_Y_5_6 / 2} 0" rpy="0 0 0" />
        <geometry>
            <box size="0.05 ${Joint_Y_5_6} 0.035"/>
        </geometry>
      </visual>
    </link>

    <link name="palbator_arm_wrist_link2" >
      <inertial>
          <origin xyz="0 ${Joint_Y_6_7 / 2} 0" rpy="0 0 0" />
          <mass value="0.1"/>
          <inertia ixx="0.1" ixy="0" ixz="0" iyy="0.1" iyz="0" izz="0.1"/>
      </inertial>
      <visual>
        <origin xyz="0 ${Joint_Y_6_7 / 2} 0" rpy="0 0 0" />
        <geometry>
            <box size="0.05 ${Joint_Y_6_7} 0.03"/>
        </geometry>
        <material name="Cyan">
          <color rgba="0 1.0 1.0 1.0"/>
      </material>
      </visual>
    </link>

    <link name="palbator_arm_wrist_link3" >
      <inertial>
          <origin xyz="0 0.0275 0.012" rpy="0 0 0" />
          <mass value="0.1"/>
          <inertia ixx="0.1" ixy="0" ixz="0" iyy="0.1" iyz="0" izz="0.1"/>
      </inertial>
      <visual>
        <origin xyz="0 0.0275 0.012" rpy="0 0 0" />
        <geometry>
            <box size="0.13 0.045 0.06"/>
        </geometry>
        <material name="Violet">
          <color rgba="1.0 0 1.0 1.0"/>
        </material>
      </visual>
    </link>
  <!--
    <link name="grip_link" >
      <visual>
        <origin xyz="0 0.0 0.0" rpy="0 0 0" />
        <geometry>
            <box size="0.02 0.08 0.06"/>
        </geometry>
        <material name="Violet">
          <color rgba="1.0 0 1.0 1.0"/>
        </material>
      </visual>
    </link>  
  -->

    <link name="palbator_arm_camera_link" >
      <inertial>
          <origin xyz="0 0 0" rpy="0 0 0"/>
          <mass value="0.1"/>
          <inertia ixx="0.1" ixy="0" ixz="0" iyy="0.1" iyz="0" izz="0.1"/>
      </inertial>
        <visual>
            <geometry>
              <box size="0.03 0.18 0.02"/>
          </geometry>
            <origin xyz="0 0 0" rpy="0 0 0"/>
        </visual>
    </link>    

    <link name="palbator_arm_end_link" />



    <joint name="palbator_arm_to_${parent}_joint" type="fixed">
      <origin xyz="0 0 0.195" rpy="0 0 3.14" />
      <child link="palbator_arm_column" />
      <parent link="${parent}"/>
    </joint>


    <joint name="palbator_arm_kinect_joint" type="fixed">
      <parent link="palbator_arm_column"/>
      <child link="palbator_arm_kinect_link"/>
        <origin xyz="0.0 0.0 1.60" rpy="0 -0.3 0" />
        <axis xyz="0 0 1" />
    </joint>

    <joint name="palbator_arm_column_joint" type="prismatic">
      <parent link="palbator_arm_column"/>
      <child link="palbator_arm_column_link"/>
      <origin xyz="0 0.1 0" rpy="0 0 0" />
      <limit effort="1000" velocity="0.3" lower="0.35" upper="1.35" />
      <axis xyz="0 0 1" />
    </joint>  

    <joint name="palbator_arm_shoulder_1_joint" type="revolute">
      <parent link="palbator_arm_column_link"/>
      <child link="palbator_arm_shoulder_link1"/>
      <origin xyz="0 0 0" rpy="0 0 0" />
      <limit effort="100" velocity="0.3" lower="-1.22" upper="1.22" />
      <axis xyz="0 0 1" />
    </joint>

    <joint name="palbator_arm_shoulder_2_joint" type="revolute">
      <parent link="palbator_arm_shoulder_link1"/>
      <child link="palbator_arm_shoulder_link2"/>
      <origin xyz="0 ${Joint_Y_2_3} ${Joint_Z_2_3}" rpy="0 0 0" />
      <limit effort="100" velocity="0.3" lower="-2.5" upper="2.27" />
      <axis xyz="0 0 -1" />
    </joint>

    <joint name="palbator_arm_shoulder_3_joint" type="revolute">
      <parent link="palbator_arm_shoulder_link2"/>
      <child link="palbator_arm_shoulder_link3"/>
      <origin xyz="0 ${Joint_Y_3_4} 0" rpy="0 0 0" />
      <limit effort="100" velocity="0.3" lower="-1.17" upper="1.6" />
      <axis xyz="-1 0 0" />
    </joint>

    <joint name="palbator_arm_wrist_1_joint" type="revolute">
      <parent link="palbator_arm_shoulder_link3"/>
      <child link="palbator_arm_wrist_link1"/>
      <origin xyz="0 ${Joint_Y_4_5} 0" rpy="0 0 0" />
      <limit effort="100" velocity="0.3" lower="-3.14" upper="3.14" />
      <axis xyz="0 1 0" />
    </joint>

    <joint name="palbator_arm_wrist_2_joint" type="revolute">
      <parent link="palbator_arm_wrist_link1"/>
      <child link="palbator_arm_wrist_link2"/>
      <origin xyz="0 ${Joint_Y_5_6} 0" rpy="0 0 0" />
      <limit effort="100" velocity="0.3" lower="-1.5" upper="2.0" />
      <axis xyz="-1 0 0" />
    </joint>

    <joint name="palbator_arm_wrist_3_joint" type="revolute">
      <parent link="palbator_arm_wrist_link2"/>
      <child link="palbator_arm_wrist_link3"/>
      <origin xyz="0 ${Joint_Y_6_7} 0" rpy="0 0 0" />
      <limit effort="100" velocity="0.3" lower="-3.14" upper="3.14" />
      <axis xyz="0 1 0" />
    </joint> 

  <!--
    <joint name="grip_left_joint" type="fixed">
      <parent link="wrist_link3"/>
      <child link="grip_link"/>
      <origin xyz="0.075 0 0" rpy="0 0 0" />
      <axis xyz="0 0 0" />
    </joint>  

    <joint name="grip_right_joint" type="fixed">
      <parent link="wrist_link3"/>
      <child link="grip_link"/>
      <origin xyz="-0.075 0 0" rpy="0 0 0" />
      <axis xyz="0 0 0" />
    </joint>   
  --> 

    <joint name="palbator_arm_end_joint" type="fixed">
      <parent link="palbator_arm_wrist_link3"/>
      <child link="palbator_arm_end_link"/>
      <origin xyz="0 0.075 0" rpy="0 0 0" />
      <axis xyz="0 0 0" />
    </joint>

    <joint name="palbator_arm_camera_joint" type="fixed">
      <parent link="palbator_arm_shoulder_link2"/>
      <child link="palbator_arm_camera_link"/>
      <origin xyz="0.0 -0.05 0.20" rpy="0 0.5 1.57" />
      <axis xyz="0 0 0" />
    </joint>

    <transmission name="tran1">
      <type>SimpleTransmission</type>
      <joint name="palbator_arm_column_joint">
        <hardwareInterface>hardware_interface/EffortJointInterface</hardwareInterface>
      </joint>
      <actuator name="motor1">
        <hardwareInterface>hardware_interface/EffortJointInterface</hardwareInterface>
        <mechanicalReduction>1</mechanicalReduction>
      </actuator>
    </transmission>

    <transmission name="tran2">
      <type>SimpleTransmission</type>
      <joint name="palbator_arm_shoulder_1_joint">
        <hardwareInterface>hardware_interface/EffortJointInterface</hardwareInterface>
      </joint>
      <actuator name="motor2">
        <hardwareInterface>hardware_interface/EffortJointInterface</hardwareInterface>
        <mechanicalReduction>1</mechanicalReduction>
      </actuator>
    </transmission>

    <transmission name="tran3">
      <type>SimpleTransmission</type>
      <joint name="palbator_arm_shoulder_2_joint">
        <hardwareInterface>hardware_interface/EffortJointInterface</hardwareInterface>
      </joint>
      <actuator name="motor3">
        <hardwareInterface>hardware_interface/EffortJointInterface</hardwareInterface>
        <mechanicalReduction>1</mechanicalReduction>
      </actuator>
    </transmission>

    <transmission name="tran4">
      <type>SimpleTransmission</type>
      <joint name="palbator_arm_shoulder_3_joint">
        <hardwareInterface>hardware_interface/EffortJointInterface</hardwareInterface>
      </joint>
      <actuator name="motor4">
        <hardwareInterface>hardware_interface/EffortJointInterface</hardwareInterface>
        <mechanicalReduction>1</mechanicalReduction>
      </actuator>
    </transmission>

    <transmission name="tran5">
      <type>SimpleTransmission</type>
      <joint name="palbator_arm_wrist_1_joint">
        <hardwareInterface>hardware_interface/EffortJointInterface</hardwareInterface>
      </joint>
      <actuator name="motor5">
        <hardwareInterface>hardware_interface/EffortJointInterface</hardwareInterface>
        <mechanicalReduction>1</mechanicalReduction>
      </actuator>
    </transmission>

    <transmission name="tran6">
      <type>SimpleTransmission</type>
      <joint name="palbator_arm_wrist_2_joint">
        <hardwareInterface>hardware_interface/EffortJointInterface</hardwareInterface>
      </joint>
      <actuator name="motor6">
        <hardwareInterface>hardware_interface/EffortJointInterface</hardwareInterface>
        <mechanicalReduction>1</mechanicalReduction>
      </actuator>
    </transmission>

    <transmission name="tran7">
      <type>SimpleTransmission</type>
      <joint name="palbator_arm_wrist_3_joint">
        <hardwareInterface>hardware_interface/EffortJointInterface</hardwareInterface>
      </joint>
      <actuator name="motor7">
        <hardwareInterface>hardware_interface/EffortJointInterface</hardwareInterface>
        <mechanicalReduction>1</mechanicalReduction>
      </actuator>
    </transmission>

<!-- GAZEBO MATERIALS -->
    <gazebo reference="palbator_arm_kinect_link">
      <material>Gazebo/Black</material>
    </gazebo>
    <gazebo reference="palbator_arm_camera_link">
      <material>Gazebo/Black</material>
    </gazebo>
<!-- GAZEBO PLUGINS -->

  <gazebo reference="palbator_arm_camera_link">
   <sensor name="palbator_arm_camera_link_camera" type="depth">
     <update_rate>20</update_rate>
     <camera>
       <horizontal_fov>1.047198</horizontal_fov>
       <image>
         <width>640</width>
         <height>480</height>
         <format>R8G8B8</format>
       </image>
       <clip>
         <near>0.05</near>
         <far>5.0</far>
       </clip>
     </camera>
   
     <plugin name="camera_plugin" filename="libgazebo_ros_openni_kinect.so">
      <baseline>0.2</baseline>
      <alwaysOn>true</alwaysOn>
      <updateRate>20.0</updateRate>
      <cameraName>camera_ir</cameraName>
      <imageTopicName>/camera/color/image_raw</imageTopicName>
      <cameraInfoTopicName>/camera/color/camera_info</cameraInfoTopicName>
      <depthImageTopicName>/camera/depth/image_raw</depthImageTopicName>
      <depthImageCameraInfoTopicName>/camera/depth/camera_info</depthImageCameraInfoTopicName>
      <pointCloudTopicName>/camera/depth/points</pointCloudTopicName>
      <frameName>palbator_arm_camera_link</frameName>
      <pointCloudCutoff>0.5</pointCloudCutoff>
      <pointCloudCutoffMax>3.0</pointCloudCutoffMax>
      <distortionK1>0</distortionK1>
      <distortionK2>0</distortionK2>
      <distortionK3>0</distortionK3>
      <distortionT1>0</distortionT1>
      <distortionT2>0</distortionT2>
      <CxPrime>0</CxPrime>
      <Cx>0</Cx>
      <Cy>0</Cy>
      <focalLength>0</focalLength>
      <hackBaseline>0</hackBaseline>
     </plugin>
   </sensor>
  </gazebo>
  <gazebo reference="palbator_arm_kinect_link">
   <sensor name="palbator_arm_kinect_link_camera" type="depth">
     <update_rate>20</update_rate>
     <camera>
       <horizontal_fov>1.047198</horizontal_fov>
       <image>
         <width>1920</width>
         <height>1080</height>
         <format>R8G8B8</format>
       </image>
       <clip>
         <near>0.05</near>
         <far>5.0</far>
       </clip>
     </camera>
   
     <plugin name="camera_plugin" filename="libgazebo_ros_openni_kinect.so">
      <baseline>0.2</baseline>
      <alwaysOn>true</alwaysOn>
      <updateRate>20.0</updateRate>
      <cameraName>kinect_ir</cameraName>
      <imageTopicName>/kinect/color/image_raw</imageTopicName>
      <cameraInfoTopicName>/kinect/color/camera_info</cameraInfoTopicName>
      <depthImageTopicName>/kinect/depth/image_raw</depthImageTopicName>
      <depthImageCameraInfoTopicName>/kinect/depth/camera_info</depthImageCameraInfoTopicName>
      <pointCloudTopicName>/kinect/depth/points</pointCloudTopicName>
      <frameName>palbator_arm_kinect_link</frameName>
      <pointCloudCutoff>0.5</pointCloudCutoff>
      <pointCloudCutoffMax>3.0</pointCloudCutoffMax>
      <distortionK1>0</distortionK1>
      <distortionK2>0</distortionK2>
      <distortionK3>0</distortionK3>
      <distortionT1>0</distortionT1>
      <distortionT2>0</distortionT2>
      <CxPrime>0</CxPrime>
      <Cx>0</Cx>
      <Cy>0</Cy>
      <focalLength>0</focalLength>
      <hackBaseline>0</hackBaseline>
     </plugin>
   </sensor>
  </gazebo>
  </xacro:macro>
</robot>