<?xml version="1.0" encoding="utf-8"?>

<robot xmlns:xacro="http://ros.org/wiki/xacro">
  <xacro:macro name="gripper" params="parent *origin">


    <!-- LINKS -->

    <link name="gripper_base_link">
      <inertial>
        <origin xyz="-9.6291E-09 -0.00038057 -0.015989" rpy="0 0 0" />
        <mass value="0.080698" />
        <inertia
          ixx="3.1972E-05"
          ixy="-1.1635E-11"
          ixz="-1.916E-12"
          iyy="2.5871E-05"
          iyz="8.8121E-07"
          izz="1.8242E-05" />
      </inertial>
      <visual>
        <origin xyz="0 0 0" rpy="0 0 0" />
        <geometry>
          <mesh filename="package://pmb2_description/meshes/gripper/gripper_base_link.STL" />
        </geometry>
        <material name="">
          <color rgba="0.2 0.2 0.2 1" />
        </material>
      </visual>
      <collision>
        <origin xyz="0 0 0" rpy="0 0 0" />
        <geometry>
          <mesh filename="package://pmb2_description/meshes/gripper/gripper_base_link.STL" />
        </geometry>
      </collision>
    </link>


    <link name="motor1_link">
      <inertial>
        <origin xyz="-6.8132E-06 -0.011983 -1.1247E-05" rpy="0 0 0" />
        <mass value="0.046265" />
        <inertia
          ixx="1.2462E-05"
          ixy="-2.2251E-09"
          ixz="1.7814E-13"
          iyy="7.8259E-06"
          iyz="-1.8276E-07"
          izz="1.0506E-05" />
      </inertial>
      <visual>
        <origin xyz="0 0 0" rpy="0 0 0" />
        <geometry>
          <mesh filename="package://pmb2_description/meshes/gripper/motor1_link.STL" />
        </geometry>
        <material name="">
          <color rgba="0.64314 0.67843 0.69804 1" />
        </material>
      </visual>
      <collision>
        <origin xyz="0 0 0" rpy="0 0 0" />
        <geometry>
           <mesh filename="package://pmb2_description/meshes/gripper/motor1_link.STL" />
        </geometry>
      </collision>
    </link>


    <link name="hand1_link">
      <inertial>
        <origin xyz="0.020 0.014965 -0.021264" rpy="0 0 0" />
        <mass value="0.034799" />
        <inertia
          ixx="1.1668E-05"
          ixy="1.0081E-14"
          ixz="1.9718E-14"
          iyy="1.5945E-05"
          iyz="1.2429E-07"
          izz="6.7071E-06" />
      </inertial>
      <visual>
        <origin xyz="-0.013 0.03 0.022" rpy="1.5707 1.5707 0" />
        <geometry>
          <mesh filename="package://pmb2_description/meshes/gripper/hand1_link.STL" />
        </geometry>
        <material name="">
          <color rgba="0.73333 0.8 0.93333 1" />
        </material>
      </visual>
      <collision>
        <origin xyz="0 0 0" rpy="0 0 0" />
        <geometry>
          <mesh filename="package://pmb2_description/meshes/gripper/hand1_link.STL" />
        </geometry>
      </collision>
    </link>


    <link name="fingertip1_1_link">
      <inertial>
        <origin xyz="-0.0010321 0.0050002 -3.5129E-05" rpy="0 0 0" />
        <mass value="0.0062622" />
        <inertia
          ixx="9.7768E-07"
          ixy="1.568E-11"
          ixz="1.5157E-09"
          iyy="1.0446E-06"
          iyz="5.6166E-12"
          izz="1.8516E-07" />
      </inertial>
      <visual>
        <origin xyz="0 0 0" rpy="1.5708 0 3.141592" />
        <geometry>
          <mesh filename="package://pmb2_description/meshes/gripper/fingertip1_1_link.STL" />
        </geometry>
        <material name="">
          <color rgba="0.64314 0.67843 0.69804 1" />
        </material>
      </visual>
      <collision>
        <origin xyz="0 0 0" rpy="0 0 0" />
        <geometry>
          <mesh filename="package://pmb2_description/meshes/gripper/fingertip1_1_link.STL" />
        </geometry>
      </collision>
    </link>


    <link name="fingertip1_2_link">
      <inertial>
        <origin xyz="-0.0010321 0.0050002 -3.5129E-05" rpy="0 0 0" />
        <mass value="0.0062622" />
        <inertia
          ixx="9.7768E-07"
          ixy="1.5681E-11"
          ixz="1.5157E-09"
          iyy="1.0446E-06"
          iyz="5.6167E-12"
          izz="1.8516E-07" />
      </inertial>
      <visual>
        <origin xyz="0 0 0" rpy="-1.5708 0 3.141592" />
        <geometry>
          <mesh filename="package://pmb2_description/meshes/gripper/fingertip1_2_link.STL" />
        </geometry>
        <material name="">
          <color rgba="0.64314 0.67843 0.69804 1" />
        </material>
      </visual>
      <collision>
        <origin xyz="0 0 0" rpy="0 0 0" />
        <geometry>
          <mesh filename="package://pmb2_description/meshes/gripper/fingertip1_2_link.STL" />
        </geometry>
      </collision>
    </link>


    <link name="motor2_link">
      <inertial>
        <origin xyz="-6.818723088E-06 -0.0119928783 5.1721160676E-06" rpy="0 0 0" />
        <mass value="0.0462274482802833" />
        <inertia
          ixx="1.24622128074611E-05"
          ixy="-2.22508786119693E-09"
          ixz="1.8268813185573E-13"
          iyy="7.82573953054426E-06"
          iyz="-1.82755036692311E-07"
          izz="1.05054790707959E-05" />
      </inertial>
      <visual>
        <origin xyz="0 0 0" rpy="0 0 0" />
        <geometry>
          <mesh filename="package://pmb2_description/meshes/gripper/motor2_link.STL" />
        </geometry>
        <material name="">
          <color rgba="0.643137254901961 0.67843137254902 0.698039215686274 1" />
        </material>
      </visual>
      <collision>
        <origin xyz="0 0 0" rpy="0 0 0" />
        <geometry>
          <mesh filename="package://pmb2_description/meshes/gripper/motor2_link.STL" />
        </geometry>
      </collision>
    </link>


    <link name="hand2_link">
      <inertial>
        <origin xyz="0.02200000008 0.01496537062 -0.02126" rpy="0 0 0" />
        <mass value="0.0347994466456583" />
        <inertia
          ixx="1.16677313950533E-05"
          ixy="1.00809740098804E-14"
          ixz="1.97184247731626E-14"
          iyy="1.59453274627637E-05"
          iyz="1.24290823789907E-07"
          izz="6.70710825023172E-06" />
      </inertial>
      <visual>
        <origin xyz="-0.013 0.03 0.022" rpy="1.5707 1.5707 0" />
        <geometry>
          <mesh filename="package://pmb2_description/meshes/gripper/hand2_link.STL" />
        </geometry>
        <material name="">
          <color rgba="0.733333333333333 0.8 0.933333333333333 1" />
        </material>
      </visual>
      <collision>
        <origin xyz="0 0 0" rpy="0 0 0" />
        <geometry>
          <mesh filename="package://pmb2_description/meshes/gripper/hand2_link.STL" />
        </geometry>
      </collision>
    </link>


    <link name="fingertip2_1_link">
      <inertial>
        <origin xyz="-0.0010321375 0.0050002 -3.512856E-05" rpy="0 0 0" />
        <mass value="0.00626220315523217" />
        <inertia
          ixx="9.7767596887376E-07"
          ixy="1.56803668594996E-11"
          ixz="1.5157444715102E-09"
          iyy="1.04455526714601E-06"
          iyz="5.61662128246886E-12"
          izz="1.8516351841874E-07" />
      </inertial>
      <visual>
        <origin xyz="0 0 0" rpy="1.5708 0 3.141592" />
        <geometry>
          <mesh filename="package://pmb2_description/meshes/gripper/fingertip2_1_link.STL" />
        </geometry>
        <material name="">
          <color rgba="0.643137254901961 0.67843137254902 0.698039215686274 1" />
        </material>
      </visual>
      <collision>
        <origin xyz="0 0 0" rpy="0 0 0" />
        <geometry>
          <mesh filename="package://pmb2_description/meshes/gripper/fingertip2_1_link.STL" />
        </geometry>
      </collision>
    </link>


    <link name="fingertip2_2_link">
      <inertial>
        <origin
          xyz="-0.001032137588 0.0050002404 -3.512856642E-05" rpy="0 0 0" />
        <mass value="0.00626220316616597" />
        <inertia
          ixx="9.77675969200664E-07"
          ixy="1.56806262615851E-11"
          ixz="1.51574413550611E-09"
          iyy="1.04455526789645E-06"
          iyz="5.6167744165921E-12"
          izz="1.85163518907813E-07" />
      </inertial>
      <visual>
        <origin xyz="0 0 0" rpy="-1.5708 0 3.141592" />
        <geometry>
          <mesh filename="package://pmb2_description/meshes/gripper/fingertip2_2_link.STL" />
        </geometry>
        <material name="">
          <color rgba="0.64313725 0.678431372 0.69803 1" />
        </material>
      </visual>
      <collision>
        <origin xyz="0 0 0" rpy="0 0 0" />
        <geometry>
          <mesh filename="package://pmb2_description/meshes/gripper/fingertip2_2_link.STL" />
        </geometry>
      </collision>
    </link>



    <!-- JOINTS -->

    <joint name="palbator_arm_wrist_3_joint" type="revolute">
      <parent link="palbator_arm_wrist_link2"/>
      <child link="gripper_base_link"/>
      <origin xyz="0 ${Joint_Y_6_7} 0" rpy="0 0 0" />
      <limit effort="100" velocity="0.3" lower="-3.14" upper="3.14" />
      <axis xyz="0 1 0" />
    </joint> 

    <joint name="gripper_motor1_joint" type="fixed">
      <origin xyz="0.0448 0.025822 -0.022247" rpy="0 0 0" />
      <parent link="gripper_base_link" />
      <child link="motor1_link" />
      <axis xyz="0 0 0" />
    </joint>

    <joint name="motor1_hand_joint" type="revolute">
      <origin xyz="0 0 0" rpy="0 0 0" />
      <parent link="motor1_link" />
      <child link="hand1_link" />
      <axis xyz="0 0 1" />
      <limit lower="-1" upper="1" effort="10" velocity="0.5" />
    </joint>

    <joint name="hand1_fingertip1_joint" type="revolute">
      <origin xyz="-0.0056 0.0877 0.0055" rpy="0 0 0" />
      <parent link="hand1_link" />
      <child link="fingertip1_1_link" />
      <axis xyz="0 0 1" />
      <limit lower="-1" upper="1" effort="10" velocity="0.5" />
    </joint>

    <joint name="hand1_fingertip2_joint"
      type="revolute">
      <origin xyz="-0.0056 0.0877 -0.0055" rpy="0 0 0" />
      <parent link="hand1_link" />
      <child link="fingertip1_2_link" />
      <axis xyz="0 0 1" />
      <limit lower="-1" upper="1" effort="10" velocity="0.5" />
    </joint>

    <joint name="gripper_motor2_joint" type="fixed">
      <origin xyz="-0.0448 0.021922 -0.022197" rpy="-3.1416 0 3.1416" />
      <parent link="gripper_base_link" />
      <child link="motor2_link" />
      <axis xyz="0 0 0" />
    </joint>

    <joint name="motor2_hand_joint" type="revolute">
      <origin xyz="0 0 0" rpy="0 0 0" />
      <parent link="motor2_link" />
      <child  link="hand2_link" />
      <axis xyz="0 0 1" />
      <limit lower="-1" upper="1" effort="10" velocity="0.5" />
    </joint>

    <joint name="hand2_fingertip1_joint" type="revolute">
      <origin xyz="-0.0056 0.0877 0.0055" rpy="0 0 0" />
      <parent link="hand2_link" />
      <child link="fingertip2_1_link" />
      <axis xyz="0 0 1" />
      <limit lower="-1" upper="1" effort="10" velocity="0.5" />
    </joint>

    <joint name="hand2_fingertip2_joint" type="revolute">
      <origin xyz="-0.0056 0.0877 -0.0055" rpy="0 0 0" />
      <parent link="hand2_link" />
      <child link="fingertip2_2_link" />
      <axis xyz="0 0 1" />
      <limit lower="-1" upper="1" effort="10" velocity="0.5" />
    </joint>



    <!-- TRANSMISSIONS -->

    <transmission name="left_finger_transmission">
      <type>SimpleTransmission</type>
      <joint name="motor1_hand_joint">
        <hardwareInterface>hardware_interface/EffortJointInterface</hardwareInterface>
      </joint>
      <actuator name="left_finger">
        <hardwareInterface>hardware_interface/EffortJointInterface</hardwareInterface>
        <mechanicalReduction>1</mechanicalReduction>
      </actuator>
    </transmission>

    <transmission name="right_finger_transmission">
      <type>SimpleTransmission</type>
      <joint name="motor2_hand_joint">
        <hardwareInterface>hardware_interface/EffortJointInterface</hardwareInterface>
      </joint>
      <actuator name="right_finger">
        <hardwareInterface>hardware_interface/EffortJointInterface</hardwareInterface>
        <mechanicalReduction>1</mechanicalReduction>
      </actuator>
    </transmission>



    <!-- GAZEBO MATERIAL PARAMS -->
    <gazebo reference="gripper_base_link">
      <material>Gazebo/Black</material>
    </gazebo>

    <gazebo reference="hand2_link">
      <material>Gazebo/LightBlue</material>
    </gazebo>

    <gazebo reference="hand1_link">
      <material>Gazebo/LightBlue</material>
    </gazebo>

    <gazebo reference="fingertip1_1_link">
      <material>Gazebo/Grey</material>
    </gazebo>

    <gazebo reference="fingertip1_2_link">
      <material>Gazebo/Grey</material>
    </gazebo>

    <gazebo reference="fingertip2_1_link">
      <material>Gazebo/Grey</material>
    </gazebo>

    <gazebo reference="fingertip2_2_link">
      <material>Gazebo/Grey</material>
    </gazebo>




    </xacro:macro>
  </robot>
